Workbook

Sheet 1. Tire List - Web Menu
B1: Complete List of Tires: | D1: Tires Organized by Segment: (this will be the "Tires" drop down on the main website navBar)
B3: ADC52 | D3: NEO SERIES LONG HAUL | E3: STANDARD SERIES LONG HAUL
B4: ADC53 | D4: Neo Fuel S | E4: ASL06
B5: ADL58 | D5: NEO FUEL D | E5: ADL58
B6: ADR24 | D6: NEO FUEL D2 | E6: ATL08
B7: ADR26 | D7: NEO FUEL D3
B8: ADR35 | D8: Neo Fuel T+ | E8: STANDARD SERIES REGIONAL
B9: ADR55 | D9: Neo Fuel T2 | E9: ASR30
B10: ADR57 | D10: Neo Fuel T3 | E10: ASR35
B11: ADR69 | D11: Neo Fuel G3 | E11: ASR69
B12: ADR78 | E12: ADR24
B13: ADW80 | D13: NEO/SAILOR SERIES REGIONAL | E13: ADR26
B14: ADW81 | D14: Neo Allroads S | E14: ADR35
B15: ADW82 | D15: Neo Allroads S+ | E15: ADR55
B16: AGC08 | D16: Neo Allroads D | E16: ADR69
B17: AGC28 | D17: Neo Allroads D+ | E17: ADR57
B18: AGC51 | D18: Neo Allroads T2 | E18: AGR26
B19: AGM10 | D19: Sailor ASR79
B20: AGM84 | D20: Sailor ASR79II | E20: STANDARD SERIES ON/OFF ROAD
B21: AGR26 | D21: Sailor ADR78/ADR78 ii | E21: ADC52
B22: ASL01 | E22: ADC53
B23: ASL01T | D23: NEO SERIES ON/OFF ROAD | E23: ADC54
B24: ASL06 | D24: Neo Construct D | E24: AGC08
B25: ASL38 | D25: Neo Construct G | E25: AGC53
B26: ASL67 | E26: AGM10
B27: ASR30 | D27: NEO SERIES WINTER | E27: AGM84
B28: ASR35 | D28: Neo Winter S
B29: ASR65 | D29: Neo Allseason D | E29: STANDARD SERIES WINTER
B30: ASR69 | E30: ADW80
B31: ASR79 | D31: NEO SERIES URBAN | E31: ADW81
B32: ATL08 | D32: Sailor AGB23 | E32: ADW82
B33: ATR65 | D33: Neo Urban G
B34: Neo Allroads D
B35: Neo Allroads D+
B36: Neo Allroads D3
B37: Neo Allroads S
B38: Neo Allroads S+
B39: Neo Allroads T2
B40: Neo Allroads T3
B41: Neo Allseason D
...

Sheet 2. Master Tire Specs  
B1: Tire Name | C1: Size | D1: Ply | E1: Rim Width | F1: Section Width | G1: Overall Diameter | I1: Tread Depth | K1: Max. Load (Single) | O1: Max. Load (Dual) | S1: LI/SS | T1: Smartway | U1: M+S | V1: 3PMSF | W1: Pattern BC | Y1: Notes:
E2: in | F2: in | G2: in | H2: mm | I2: mm | J2: 32nds | K2: lbs | L2: psi | M2: kg | N2: kPa | O2: lbs | P2: psi | Q2: kg | R2: kPa
B3: ADC52 | C3: 11R22.5 | D3: 16 | E3: 8.25 | F3: 11 | G3: 42 | H3: 1068 | I3: 24 | J3: 30.2 | K3: 6614 | L3: 120 | M3: 3000 | N3: 830 | O3: 6008 | P3: 120 | Q3: 2725 | R3: 830 | S3: 146/143K | U3: • | V3: • | W3: ADC52
C4: 13R22.5 | D4: 18 | E4: 9.75 | F4: 12.4 | G4: 44.9 | H4: 1141 | I4: 24 | J4: 30.2 | K4: 8267 | L4: 120 | M4: 3750 | N4: 830 | O4: 7606 | P4: 120 | Q4: 3450 | R4: 830 | S4: 154/151K | U4: • | V4: • | W4: ADC52
C5: 315/80R22.5 | D5: 20 | E5: 9 | F5: 12.5 | G5: 43.1 | H5: 1095 | I5: 23 | J5: 29 | K5: 9094 | L5: 131 | M5: 4125 | N5: 900 | O5: 8267 | P5: 131 | Q5: 3750 | R5: 900 | S5: 157/154K | U5: • | V5: • | W5: ADC52
B6: ADC53 | C6: 11.00R20 | D6: 18 | E6: 8 | F6: 11.3 | G6: 42.9 | H6: 1091 | I6: 19 | J6: 23.3 | K6: 7826 | L6: 135 | M6: 3550 | N6: 930 | O6: 7165 | P6: 135 | Q6: 3250 | R6: 930 | S6: 152/149K | U6: • | V6: • | W6: ADC53
C7: 11R22.5 | D7: 16 | E7: 8.25 | F7: 10.9 | G7: 41.9 | H7: 1065 | I7: 23 | J7: 28.3 | K7: 6614 | L7: 120 | M7: 3000 | N7: 830 | O7: 6008 | P7: 120 | Q7: 2725 | R7: 830 | S7: 146/143L | U7: • | V7: • | W7: ADC53
C8: 11R24.5 | D8: 16 | E8: 8.25 | F8: 11.4 | G8: 43.5 | H8: 1106 | I8: 23 | J8: 28.3 | K8: 7165 | L8: 120 | M8: 3250 | N8: 830 | O8: 6614 | P8: 120 | Q8: 3000 | R8: 830 | S8: 149/146L | U8: • | W8: ADC53
C9: 12.00R20 | D9: 18 | E9: 8.5 | F9: 12.3 | G9: 44.5 | H9: 1129 | I9: 21 | J9: 26 | K9: 8267 | L9: 120 | M9: 3750 | N9: 830 | O9: 7606 | P9: 120 | Q9: 3450 | R9: 830 | S9: 154/151K | U9: • | V9: • | W9: ADC53
C10: 12.00R24 | D10: 20 | E10: 8.5 | F10: 12.3 | G10: 48.4 | H10: 1230 | I10: 21 | J10: 26 | K10: 9921 | L10: 131 | M10: 4500 | N10: 900 | O10: 9094 | P10: 131 | Q10: 4125 | R10: 900 | S10: 160/157K | U10: • | V10: • | W10: ADC53
C11: 12R22.5 | D11: 18 | E11: 9 | F11: 11.9 | G11: 42.6 | H11: 1082 | I11: 20 | J11: 24.6 | K11: 7826 | L11: 135 | M11: 3550 | N11: 930 | O11: 7165 | P11: 135 | Q11: 3250 | R11: 930 | S11: 152/149L | U11: • | V11: • | W11: ADC53
C12: 13R22.5 | D12: 18 | E12: 9.75 | F12: 12.5 | G12: 44.4 | H12: 1128 | I12: 21 | J12: 26 | K12: 8267 | L12: 120 | M12: 3750 | N12: 830 | O12: 7606 | P12: 120 | Q12: 3450 | R12: 830 | S12: 154/151K | U12: • | V12: • | W12: ADC53
C13: 275/70R22.5 | D13: 18 | E13: 8.25 | F13: 10.8 | G13: 38.3 | H13: 972 | I13: 21 | J13: 26 | K13: 6945 | L13: 131 | M13: 3150 | N13: 900 | O13: 6393 | P13: 131 | Q13: 2900 | R13: 900 | S13: 148/145L | U13: • | V13: • | W13: ADC53
C14: 315/80R22.5 | D14: 18 | E14: 9 | F14: 12.4 | G14: 42.8 | H14: 1088 | I14: 20 | J14: 24.6 | K14: 8267 | L14: 120 | M14: 3750 | N14: 830 | O14: 7606 | P14: 120 | Q14: 3450 | R14: 830 | S14: 154/151M | U14: • | V14: • | W14: ADC53
C15: 315/80R22.5 | D15: 20 | E15: 9 | F15: 12.5 | G15: 42.8 | H15: 1088 | I15: 20 | J15: 24.6 | K15: 9094 | L15: 131 | M15: 4125 | N15: 900 | O15: 8267 | P15: 131 | Q15: 3750 | R15: 900 | S15: 157/154M | U15: • | V15: • | W15: ADC53
B16: ADL58 | C16: 11R22.5 | D16: 16 | E16: 8.25 | F16: 11 | G16: 42 | H16: 1066 | I16: 21 | J16: 26 | K16: 6614 | L16: 120 | M16: 3000 | N16: 830 | O16: 6008 | P16: 120 | Q16: 2725 | R16: 830 | S16: 146/143L | U16: • | W16: ADL58-ECO
C17: 11R24.5 | D17: 16 | E17: 8.25 | F17: 11.1 | G17: 43.5 | H17: 1104 | I17: 21 | J17: 26 | K17: 7165 | L17: 120 | M17: 3250 | N17: 830 | O17: 6614 | P17: 120 | Q17: 3000 | R17: 830 | S17: 149/146L | U17: • | W17: ADL58-ECO
B18: ADR24 | C18: 12R24.5 | D18: 18 | E18: 9 | F18: 11.9 | G18: 44.7 | H18: 1135 | I18: 21 | J18: 26 | K18: 8267 | L18: 135 | M18: 3750 | N18: 930 | O18: 7606 | P18: 135 | Q18: 3450 | R18: 930 | S18: 154/151M | U18: • | W18: ADR24
B19: ADR26 | C19: 10.00R20 | D19: 18 | E19: 7.5 | F19: 10.7 | G19: 41.6 | H19: 1056 | I19: 18 | J19: 22 | K19: 7165 | L19: 135 | M19: 3250 | N19: 930 | O19: 6614 | P19: 135 | Q19: 3000 | R19: 930 | S19: 149/146K | U19: • | V19: • | W19: ADR26
C20: 11.00R20 | D20: 18 | E20: 8 | F20: 11.3 | G20: 43 | H20: 1091 | I20: 19 | J20: 23.3 | K20: 7826 | L20: 135 | M20: 3550 | N20: 930 | O20: 7165 | P20: 135 | Q20: 3250 | R20: 930 | S20: 152/149L | U20: • | V20: • | W20: ADR26
C21: 11R22.5 | D21: 16 | E21: 8.25 | F21: 11 | G21: 41.8 | H21: 1063 | I21: 21 | J21: 26 | K21: 6945 | L21: 120 | M21: 3150 | N21: 830 | O21: 6173 | P21: 120 | Q21: 2800 | R21: 830 | S21: 148/144M | U21: • | V21: • | W21: ADR26
C22: 11R24.5 | D22: 16 | E22: 8.25 | F22: 11.1 | G22: 43.5 | H22: 1104 | I22: 21 | J22: 26 | K22: 7165 | L22: 120 | M22: 3250 | N22: 830 | O22: 6614 | P22: 120 | Q22: 3000 | R22: 830 | S22: 149/146L | U22: • | W22: ADR26
C23: 12.00R20 | D23: 22 | E23: 8.5 | F23: 12.3 | G23: 44.4 | H23: 1127 | I23: 19 | J23: 23.9 | K23: 9370 | L23: 141 | M23: 4250 | N23: 970 | O23: 8543 | P23: 141 | Q23: 3875 | R23: 970 | S23: 158/155J | U23: • | V23: • | W23: ADR26
C24: 9.00R20 | D24: 16 | E24: 7 | F24: 10.2 | G24: 40.4 | H24: 1025 | I24: 17 | J24: 21.4 | K24: 6173 | L24: 131 | M24: 2800 | N24: 900 | O24: 5842 | P24: 131 | Q24: 2650 | R24: 900 | S24: 144/142M | U24: • | V24: • | W24: ADR26
B25: ADR35 | C25: 205/75R17.5 | D25: 14 | E25: 6 | F25: 8.2 | G25: 29.8 | H25: 757 | I25: 16 | J25: 20.2 | K25: 3417 | L25: 110 | M25: 1550 | N25: 760 | O25: 3197 | P25: 110 | Q25: 1450 | R25: 760 | S25: 124/122M | U25: • | V25: • | W25: ADR35
C26: 215/75R17.5 | D26: 18 | E26: 6 | F26: 8.4 | G26: 30.3 | H26: 769 | I26: 16 | J26: 20.2 | K26: 4806 | L26: 120 | M26: 2180 | N26: 830 | O26: 4542 | P26: 120 | Q26: 2060 | R26: 830 | S26: 135/133J | U26: • | V26: • | W26: ADR35
C27: 235/75R17.5 | D27: 18 | E27: 6.75 | F27: 9.3 | G27: 31.5 | H27: 801 | I27: 17 | J27: 21.4 | K27: 6008 | L27: 131 | M27: 2725 | N27: 900 | O27: 5677 | P27: 131 | Q27: 2575 | R27: 900 | S27: 143/141J | U27: • | V27: • | W27: ADR35
C28: 245/70R17.5 | D28: 18 | E28: 7.5 | F28: 9.9 | G28: 31.2 | H28: 792 | I28: 17 | J28: 20.8 | K28: 4938 | L28: 131 | M28: 2240 | N28: 900 | O28: 4674 | P28: 131 | Q28: 2120 | R28: 900 | S28: 136/134M | U28: • | V28: • | W28: ADR35
B29: ADR55 | C29: 10R22.5 | D29: 16 | E29: 7.5 | F29: 10.2 | G29: 40.4 | H29: 1025 | I29: 16 | J29: 19.5 | K29: 6173 | L29: 131 | M29: 2800 | N29: 900 | O29: 5842 | P29: 131 | Q29: 2650 | R29: 900 | S29: 144/142M | U29: • | V29: • | W29: ADR55
C30: 12R22.5 | D30: 18 | E30: 9 | F30: 11.8 | G30: 42.9 | H30: 1090 | I30: 23 | J30: 29 | K30: 7826 | L30: 135 | M30: 3550 | N30: 930 | O30: 7165 | P30: 135 | Q30: 3250 | R30: 930 | S30: 152/149M | U30: • | V30: • | W30: ADR55
C31: 255/70R22.5 | D31: 16 | E31: 7.5 | F31: 10 | G31: 36.9 | H31: 936 | I31: 20 | J31: 25.2 | K31: 5512 | L31: 120 | M31: 2500 | N31: 830 | O31: 5071 | P31: 120 | Q31: 2300 | R31: 830 | S31: 140/137M | U31: • | V31: • | W31: ADR55
C32: 275/70R22.5 | D32: 18 | E32: 8.25 | F32: 10.8 | G32: 38.4 | H32: 975 | I32: 20 | J32: 25.2 | K32: 6945 | L32: 131 | M32: 3150 | N32: 900 | O32: 6393 | P32: 131 | Q32: 2900 | R32: 900 | S32: 148/145M | U32: • | V32: • | W32: ADR55
B33: ADR57 | C33: 11R22.5 | D33: 16 | E33: 8.25 | F33: 10.9 | G33: 41.9 | H33: 1063 | I33: 21 | J33: 26 | K33: 6614 | L33: 120 | M33: 3000 | N33: 830 | O33: 6008 | P33: 120 | Q33: 2725 | R33: 830 | S33: 146/143M | U33: • | W33: ADR57
C34: 11R24.5 | D34: 16 | E34: 8.25 | F34: 11.1 | G34: 43.5 | H34: 1104 | I34: 21 | J34: 26 | K34: 7165 | L34: 120 | M34: 3250 | N34: 830 | O34: 6614 | P34: 120 | Q34: 3000 | R34: 830 | S34: 149/146M | U34: • | W34: ADR57
B35: ADR69 | C35: 315/70R22.5 | D35: 18 | E35: 9 | F35: 12.3 | G35: 40.5 | H35: 1029 | I35: 23 | J35: 29 | K35: 7606 | L35: 120 | M35: 3450 | N35: 830 | O35: 6945 | P35: 120 | Q35: 3150 | R35: 830 | S35: 152/148M | U35: • | V35: • | W35: ADR69
C36: 315/80R22.5 | D36: 20 | E36: 9 | F36: 12.6 | G36: 43.1 | H36: 1094 | I36: 23 | J36: 29 | K36: 9094 | L36: 131 | M36: 4125 | N36: 900 | O36: 8267 | P36: 131 | Q36: 3750 | R36: 900 | S36: 157/154M | U36: • | V36: • | W36: ADR69
B37: ADR78 | C37: 12R22.5 | D37: 18 | E37: 9 | F37: 11.9 | G37: 43.1 | H37: 1096 | I37: 23 | J37: 28.3 | K37: 7826 | L37: 135 | M37: 3550 | N37: 930 | O37: 7165 | P37: 135 | Q37: 3250 | R37: 930 | S37: 152/149M | U37: • | W37: ADR78
C38: 245/70R19.5 | D38: 18 | E38: 7.5 | F38: 9.8 | G38: 33.7 | H38: 855 | I38: 17 | J38: 21.4 | K38: 6173 | L38: 131 | M38: 2800 | N38: 900 | O38: 5842 | P38: 131 | Q38: 2650 | R38: 900 | S38: 144/142J | U38: • | V38: • | W38: ADR78
B39: ADW80 | C39: 315/70R22.5 | D39: 18 | E39: 9 | F39: 12.4 | G39: 40.7 | H39: 1033 | I39: 24 | J39: 30.2 | K39: 7606 | L39: 120 | M39: 3450 | N39: 830 | O39: 6945 | P39: 120 | Q39: 3150 | R39: 830 | S39: 152/148M | U39: • | V39: • | W39: ADW80
C40: 315/80R22.5 | D40: 18 | E40: 9 | F40: 12.6 | G40: 43.2 | H40: 1096 | I40: 24 | J40: 30.2 | K40: 8267 | L40: 120 | M40: 3750 | N40: 830 | O40: 7606 | P40: 120 | Q40: 3450 | R40: 830 | S40: 154/151M | U40: • | V40: • | W40: ADW80
...

Sheet 3.Tire Content
A2: Tire Name | B2: ='2. Master Tire Specs '!B173
B4: Size | C4: Ply | D4: Rim Width | E4: Section Width | F4: Overall Diameter | H4: Tread Depth | J4: Max. Load (Single) | N4: Max. Load (Dual) | R4: LI/SS | S4: Smartway | T4: M+S | U4: 3PMSF
B5: {='2. Master Tire Specs '!C173:V175} | C5: 16 | D5: 9 | E5: 296 | F5: 39.9 | G5: 1014 | H5: 15 | I5: 18.9 | J5: 6600 | K5: 120 | L5: 3000 | M5: 830 | N5: 5995 | O5: 120 | P5: 2725 | Q5: 830 | R5: 146/143M | S5: 0 | T5: • | U5: 0
B6: 11R22.5 | C6: 16 | D6: 8.25 | E6: 11.1 | F6: 41.4 | G6: 1051 | H6: 15 | I6: 18.9 | J6: 6614 | K6: 120 | L6: 3000 | M6: 830 | N6: 6008 | O6: 120 | P6: 2725 | Q6: 830 | R6: 146/143M | S6: • | T6: • | U6: 0
B7: 11R24.5 | C7: 16 | D7: 8.25 | E7: 11.4 | F7: 43 | G7: 1093 | H7: 15 | I7: 18.9 | J7: 7165 | K7: 120 | L7: 3250 | M7: 830 | N7: 6614 | O7: 120 | P7: 3000 | Q7: 830 | R7: 149/146M | S7: • | T7: • | U7: 0
A10: Segment/Category | B10: Premium Long Haul
A11: subtitle | B11: Engineered for long-distance journeys ensuring high-speed stability, fuel efficiency, and endurance mile after mile.
A13: Tire hero image | B13: hero-1
A14: bgTruck | B14: bg-long-haul-1
A15: pos | B15: pos-steer-tire
A17: Bullet points | B17: 4 longitudinal grooves on the tread providing excellent guiding performance.
B18: Optimized ground pressure distribution to ensure product life.
B19: SATT construction for better endurance, effectively securing tire life.
B20: Low rolling resistance formula in tread to maximize fuel efficiency.
A22: Feature title 1 | B22: OPTIMIZED Z-SHAPED GROOVE DESIGN
A23: Feature body 1 | B23: Z-shaped straight grooves with optimized geometry and higher pattern saturation ensure even wear and higher mileage, delivering long-lasting tread life and consistent performance on long-haul routes.
A24: Feature image 1 | B24: Neo-Fuel-G3-f1
A26: Feature title 2 | B26: CLOSED SHOULDER STRUCTURE
A27: Feature body 2 | B27: A reinforced closed shoulder design enhances heat dissipation and traction while maintaining even wear performance—improving handling stability and extending tire durability.
A28: Feature image 2 | B28: Neo-Fuel-G3-f2
A30: Feature title 3 | B30: ADVANCED 3D SIPE TECHNOLOGY
A31: Feature body 3 | B31: New 3D sipe solutions in the central and shoulder tread blocks enable better block movement, enhancing snow grip and traction while providing regular wear, lower rolling resistance, reduced noise, and improved control in both dry and wet conditions.
A32: Feature image 3 | B32: Neo-Fuel-G3-f3
A36: Tire Name | B36: ='2. Master Tire Specs '!B3
B38: Size | C38: Ply | D38: Rim Width | E38: Section Width | F38: Overall Diameter | H38: Tread Depth | J38: Max. Load (Single) | N38: Max. Load (Dual) | R38: LI/SS | S38: Smartway | T38: M+S | U38: 3PMSF
B39: {='2. Master Tire Specs '!C3:V5}
A44: Segment/Category
A45: subtitle
A47: Tire hero image
A48: bgTruck
A49: pos
A51: Bullet points
A56: Feature title 1
A57: Feature body 1
A58: Feature image 1
A60: Feature title 2
A61: Feature body 2
A62: Feature image 2
... A66: Feature image 3
A69: Tire Name | B69: ='2. Master Tire Specs '!B6
...
